Workbook
Name Slicer_Individual_Hashtags: #N/A
Name Slicer_Platform: #N/A
Name Slicer_Week_Start_Date: #N/A

Sheet Posts
A1: Post ID | B1: Platform | C1: Date | D1: Content Type | E1: Post Text | F1: Likes | G1: Shares | H1: Comments | I1: Impressions | J1: Engagement Rate | K1: Reach | L1: Clicks | M1: Hashtags | N1: Individual Hashtags | O1: Campaign_Name | P1: Engagement
A2: P220 | B2: Instagram | C2: 2024-06-02 | D2: Story | E2: Check out our latest story on instagram! | F2: 84 | G2: 897 | H2: 85 | I2: 588 | J2: =(F2+G2+H2)/I2 -> 1.8129252 | K2: 8 | L2: 12 | M2: #FutureOfDriving,#AnytimeIsTeslaTime | N2: #FutureOfDriving | O2: CybertruckLaunch | P2: =F2+G2+H2 -> 1066
A3: P058 | B3: Instagram | C3: 2025-04-15 | D3: Reel | E3: Check out our latest reel on instagram! | F3: 103 | G3: 770 | H3: 19 | I3: 1030 | J3: =(F3+G3+H3)/I3 -> 0.86601942 | K3: 410 | L3: 262 | M3: #TeslaCoInnovation,#BetterWithTesla | N3: #AnytimeIsTeslaTime | O3: ModelYCampaign | P3: =F3+G3+H3 -> 892
A4: P232 | B4: Twitter | C4: 2025-04-29 | D4: Story | E4: Check out our latest story on twitter! | F4: 249 | G4: 592 | H4: 230 | I4: 1494 | J4: =(F4+G4+H4)/I4 -> 0.71686747 | K4: 1044 | L4: 201 | M4: #TeslaCoInnovation | N4: #TeslaCoInnovation | O4: FSDUpdate | P4: =F4+G4+H4 -> 1071
A5: P178 | B5: Instagram | C5: 2024-11-07 | D5: Video | E5: Check out our latest video on instagram! | F5: 129 | G5: 643 | H5: 136 | I5: 1290 | J5: =(F5+G5+H5)/I5 -> 0.70387597 | K5: 839 | L5: 238 | M5: #EVRevolution | N5: #BetterWithTesla | O5: SustainabilityDrive | P5: =F5+G5+H5 -> 908
A6: P175 | B6: Instagram | C6: 2025-01-17 | D6: Reel | E6: Check out our latest reel on instagram! | F6: 142 | G6: 784 | H6: 183 | I6: 1704 | J6: =(F6+G6+H6)/I6 -> 0.6508216 | K6: 995 | L6: 154 | M6: #EVRevolution,#TeslaCoInnovation | N6: #TeslaCoInnovation | O6: CybertruckLaunch | P6: =F6+G6+H6 -> 1109
A7: P062 | B7: Twitter | C7: 2024-11-22 | D7: Carousel | E7: Check out our latest carousel on twitter! | F7: 53 | G7: 81 | H7: 379 | I7: 954 | J7: =(F7+G7+H7)/I7 -> 0.53773585 | K7: 7 | L7: 148 | M7: #TeslaCoInnovation | N7: #EVRevolution | O7: ModelYCampaign | P7: =F7+G7+H7 -> 513
A8: P264 | B8: Twitter | C8: 2025-01-30 | D8: Image | E8: Check out our latest image on twitter! | F8: 59 | G8: 163 | H8: 93 | I8: 590 | J8: =(F8+G8+H8)/I8 -> 0.53389831 | K8: 475 | L8: 293 | M8: #TeslaCoInnovation | N8: #EVRevolution | O8: ModelYCampaign | P8: =F8+G8+H8 -> 315
A9: P143 | B9: YouTube | C9: 2024-10-02 | D9: Carousel | E9: Check out our latest carousel on youtube! | F9: 80 | G9: 362 | H9: 80 | I9: 1040 | J9: =(F9+G9+H9)/I9 -> 0.50192308 | K9: 349 | L9: 117 | M9: #EVRevolution | N9: #TeslaCoInnovation | O9: SustainabilityDrive | P9: =F9+G9+H9 -> 522
A10: P210 | B10: YouTube | C10: 2025-02-19 | D10: Image | E10: Check out our latest image on youtube! | F10: 257 | G10: 966 | H10: 398 | I10: 3341 | J10: =(F10+G10+H10)/I10 -> 0.48518408 | K10: 2753 | L10: 287 | M10: #TeslaCoInnovation | N10: #TeslaCoInnovation | O10: ModelYCampaign | P10: =F10+G10+H10 -> 1621
A11: P070 | B11: Facebook | C11: 2025-04-02 | D11: Video | E11: Check out our latest video on facebook! | F11: 199 | G11: 772 | H11: 400 | I11: 3582 | J11: =(F11+G11+H11)/I11 -> 0.38274707 | K11: 2988 | L11: 43 | M11: #TeslaCoInnovation | N11: #TeslaCoInnovation | O11: ModelYCampaign | P11: =F11+G11+H11 -> 1371
A12: P214 | B12: Instagram | C12: 2024-12-23 | D12: Image | E12: Check out our latest image on instagram! | F12: 521 | G12: 746 | H12: 315 | I12: 4168 | J12: =(F12+G12+H12)/I12 -> 0.37955854 | K12: 3399 | L12: 282 | M12: #FutureOfDriving | N12: #EVRevolution | O12: SustainabilityDrive | P12: =F12+G12+H12 -> 1582
A13: P053 | B13: YouTube | C13: 2025-02-24 | D13: Carousel | E13: Check out our latest carousel on youtube! | F13: 804 | G13: 639 | H13: 43 | I13: 4020 | J13: =(F13+G13+H13)/I13 -> 0.36965174 | K13: 3144 | L13: 11 | M13: #FutureOfDriving | N13: #TeslaCoInnovation | O13: FSDUpdate | P13: =F13+G13+H13 -> 1486
A14: P102 | B14: Twitter | C14: 2024-09-18 | D14: Reel | E14: Check out our latest reel on twitter! | F14: 1000 | G14: 978 | H14: 162 | I14: 6000 | J14: =(F14+G14+H14)/I14 -> 0.35666667 | K14: 5221 | L14: 223 | M14: #EVRevolution | N14: #TeslaCoInnovation | O14: CybertruckLaunch | P14: =F14+G14+H14 -> 2140
A15: P124 | B15: YouTube | C15: 2025-04-06 | D15: Carousel | E15: Check out our latest carousel on youtube! | F15: 736 | G15: 771 | H15: 225 | I15: 5152 | J15: =(F15+G15+H15)/I15 -> 0.33618012 | K15: 4706 | L15: 19 | M15: #FutureOfDriving | N15: #FutureOfDriving | P15: =F15+G15+H15 -> 1732
A16: P121 | B16: Instagram | C16: 2024-07-29 | D16: Story | E16: Check out our latest story on instagram! | F16: 498 | G16: 701 | H16: 412 | I16: 4980 | J16: =(F16+G16+H16)/I16 -> 0.32349398 | K16: 4185 | L16: 185 | M16: #FutureOfDriving | N16: #FutureOfDriving | O16: CybertruckLaunch | P16: =F16+G16+H16 -> 1611
A17: P224 | B17: Facebook | C17: 2025-05-13 | D17: Image | E17: Check out our latest image on facebook! | F17: 602 | G17: 594 | H17: 156 | I17: 4214 | J17: =(F17+G17+H17)/I17 -> 0.32083531 | K17: 3363 | L17: 164 | M17: #FutureOfDriving | N17: #EVRevolution | O17: FSDUpdate | P17: =F17+G17+H17 -> 1352
A18: P154 | B18: Instagram | C18: 2024-10-09 | D18: Carousel | E18: Check out our latest carousel on instagram! | F18: 985 | G18: 932 | H18: 287 | I18: 6895 | J18: =(F18+G18+H18)/I18 -> 0.31965192 | K18: 6757 | L18: 64 | M18: #EVRevolution | N18: #FutureOfDriving | O18: SustainabilityDrive | P18: =F18+G18+H18 -> 2204
A19: P119 | B19: Instagram | C19: 2025-02-07 | D19: Reel | E19: Check out our latest reel on instagram! | F19: 1970 | G19: 675 | H19: 478 | I19: 9850 | J19: =(F19+G19+H19)/I19 -> 0.31705584 | K19: 8924 | L19: 117 | M19: #FutureOfDriving | N19: #FutureOfDriving | O19: CybertruckLaunch | P19: =F19+G19+H19 -> 3123
A20: P287 | B20: Instagram | C20: 2024-08-15 | D20: Reel | E20: Check out our latest reel on instagram! | F20: 1164 | G20: 616 | H20: 324 | I20: 6984 | J20: =(F20+G20+H20)/I20 -> 0.30126002 | K20: 6636 | L20: 82 | M20: #TeslaCoInnovation | N20: #FutureOfDriving | O20: SustainabilityDrive | P20: =F20+G20+H20 -> 2104
A21: P204 | B21: Instagram | C21: 2025-01-01 | D21: Carousel | E21: Check out our latest carousel on instagram! | F21: 2234 | G21: 653 | H21: 432 | I21: 11170 | J21: =(F21+G21+H21)/I21 -> 0.29713518 | K21: 10569 | L21: 198 | M21: #TeslaCoInnovation | N21: #EVRevolution | O21: CybertruckLaunch | P21: =F21+G21+H21 -> 3319
A22: P066 | B22: Twitter | C22: 2024-07-26 | D22: Carousel | E22: Check out our latest carousel on twitter! | F22: 432 | G22: 171 | H22: 280 | I22: 3024 | J22: =(F22+G22+H22)/I22 -> 0.29199735 | K22: 2285 | L22: 184 | M22: #FutureOfDriving | N22: #FutureOfDriving | O22: SustainabilityDrive | P22: =F22+G22+H22 -> 883
A23: P183 | B23: Instagram | C23: 2024-12-17 | D23: Story | E23: Check out our latest story on instagram! | F23: 360 | G23: 590 | H23: 393 | I23: 4680 | J23: =(F23+G23+H23)/I23 -> 0.28696581 | K23: 4322 | L23: 208 | M23: #TeslaCoInnovation | N23: #TeslaCoInnovation | O23: SustainabilityDrive | P23: =F23+G23+H23 -> 1343
A24: P031 | B24: Instagram | C24: 2024-12-16 | D24: Text | E24: Check out our latest text on instagram! | F24: 438 | G24: 153 | H24: 275 | I24: 3066 | J24: =(F24+G24+H24)/I24 -> 0.28245271 | K24: 2701 | L24: 282 | M24: #TeslaCoInnovation,#AnytimeIsTeslaTime | N24: #TeslaCoInnovation | O24: ModelYCampaign | P24: =F24+G24+H24 -> 866
A25: P093 | B25: Instagram | C25: 2024-12-11 | D25: Video | E25: Check out our latest video on instagram! | F25: 1431 | G25: 951 | H25: 26 | I25: 8586 | J25: =(F25+G25+H25)/I25 -> 0.28045656 | K25: 8396 | L25: 150 | M25: #FutureOfDriving | N25: #FutureOfDriving | O25: FSDUpdate | P25: =F25+G25+H25 -> 2408
A26: P263 | B26: Instagram | C26: 2024-08-20 | D26: Reel | E26: Check out our latest reel on instagram! | F26: 2603 | G26: 690 | H26: 205 | I26: 13015 | J26: =(F26+G26+H26)/I26 -> 0.26876681 | K26: 12130 | L26: 20 | M26: #EVRevolution | N26: #TeslaCoInnovation | P26: =F26+G26+H26 -> 3498
A27: P248 | B27: Facebook | C27: 2025-02-02 | D27: Story | E27: Check out our latest story on facebook! | F27: 886 | G27: 126 | H27: 153 | I27: 4430 | J27: =(F27+G27+H27)/I27 -> 0.26297968 | K27: 4037 | L27: 212 | M27: #FutureOfDriving | N27: #TeslaCoInnovation | O27: ModelYCampaign | P27: =F27+G27+H27 -> 1165
A28: P244 | B28: YouTube | C28: 2024-10-25 | D28: Video | E28: Check out our latest video on youtube! | F28: 4661 | G28: 935 | H28: 433 | I28: 23305 | J28: =(F28+G28+H28)/I28 -> 0.25869985 | K28: 22583 | L28: 63 | M28: #FutureOfDriving | N28: #AnytimeIsTeslaTime | O28: SustainabilityDrive | P28: =F28+G28+H28 -> 6029
A29: P259 | B29: Facebook | C29: 2025-02-10 | D29: Text | E29: Check out our latest text on facebook! | F29: 562 | G29: 158 | H29: 149 | I29: 3372 | J29: =(F29+G29+H29)/I29 -> 0.25771056 | K29: 2940 | L29: 93 | M29: #FutureOfDriving | N29: #FutureOfDriving | O29: SustainabilityDrive | P29: =F29+G29+H29 -> 869
A30: P219 | B30: Twitter | C30: 2025-01-28 | D30: Reel | E30: Check out our latest reel on twitter! | F30: 1188 | G30: 470 | H30: 174 | I30: 7128 | J30: =(F30+G30+H30)/I30 -> 0.25701459 | K30: 6145 | L30: 270 | M30: #FutureOfDriving | N30: #EVRevolution | O30: FSDUpdate | P30: =F30+G30+H30 -> 1832
A31: P226 | B31: Instagram | C31: 2024-08-07 | D31: Carousel | E31: Check out our latest carousel on instagram! | F31: 1741 | G31: 164 | H31: 318 | I31: 8705 | J31: =(F31+G31+H31)/I31 -> 0.25537048 | K31: 8272 | L31: 121 | M31: #EVRevolution | N31: #FutureOfDriving | P31: =F31+G31+H31 -> 2223
A32: P265 | B32: Twitter | C32: 2025-02-20 | D32: Carousel | E32: Check out our latest carousel on twitter! | F32: 1877 | G32: 745 | H32: 225 | I32: 11262 | J32: =(F32+G32+H32)/I32 -> 0.25279702 | K32: 10967 | L32: 41 | M32: #TeslaCoInnovation | N32: #FutureOfDriving | O32: ModelYCampaign | P32: =F32+G32+H32 -> 2847
A33: P239 | B33: YouTube | C33: 2025-02-24 | D33: Text | E33: Check out our latest text on youtube! | F33: 4188 | G33: 942 | H33: 118 | I33: 20940 | J33: =(F33+G33+H33)/I33 -> 0.25062082 | K33: 20471 | L33: 102 | M33: #EVRevolution | N33: #FutureOfDriving | O33: CybertruckLaunch | P33: =F33+G33+H33 -> 5248
A34: P277 | B34: Facebook | C34: 2025-04-06 | D34: Image | E34: Check out our latest image on facebook! | F34: 4236 | G34: 711 | H34: 298 | I34: 21180 | J34: =(F34+G34+H34)/I34 -> 0.24763928 | K34: 20516 | L34: 238 | M34: #TeslaCoInnovation | N34: #FutureOfDriving | O34: CybertruckLaunch | P34: =F34+G34+H34 -> 5245
A35: P297 | B35: Twitter | C35: 2024-12-24 | D35: Text | E35: Check out our latest text on twitter! | F35: 2166 | G35: 354 | H35: 117 | I35: 10830 | J35: =(F35+G35+H35)/I35 -> 0.2434903 | K35: 10245 | L35: 24 | M35: #TeslaCoInnovation | N35: #EVRevolution | O35: FSDUpdate | P35: =F35+G35+H35 -> 2637
A36: P181 | B36: YouTube | C36: 2025-03-21 | D36: Image | E36: Check out our latest image on youtube! | F36: 606 | G36: 789 | H36: 470 | I36: 7878 | J36: =(F36+G36+H36)/I36 -> 0.23673521 | K36: 7389 | L36: 239 | M36: #FutureOfDriving | N36: #TeslaCoInnovation | O36: ModelYCampaign | P36: =F36+G36+H36 -> 1865
A37: P246 | B37: Facebook | C37: 2024-10-11 | D37: Image | E37: Check out our latest image on facebook! | F37: 400 | G37: 680 | H37: 434 | I37: 6400 | J37: =(F37+G37+H37)/I37 -> 0.2365625 | K37: 5472 | L37: 160 | M37: #EVRevolution | N37: #EVRevolution | O37: ModelYCampaign | P37: =F37+G37+H37 -> 1514
A38: P123 | B38: Instagram | C38: 2024-06-14 | D38: Story | E38: Check out our latest story on instagram! | F38: 4363 | G38: 649 | H38: 140 | I38: 21815 | J38: =(F38+G38+H38)/I38 -> 0.23616777 | K38: 21481 | L38: 157 | M38: #EVRevolution | N38: #TeslaCoInnovation | O38: ModelYCampaign | P38: =F38+G38+H38 -> 5152
A39: P120 | B39: Facebook | C39: 2024-10-21 | D39: Story | E39: Check out our latest story on facebook! | F39: 780 | G39: 928 | H39: 301 | I39: 8580 | J39: =(F39+G39+H39)/I39 -> 0.23414918 | K39: 8081 | L39: 91 | M39: #TeslaCoInnovation | N39: #TeslaCoInnovation | O39: SustainabilityDrive | P39: =F39+G39+H39 -> 2009
A40: P141 | B40: Twitter | C40: 2024-08-31 | D40: Image | E40: Check out our latest image on twitter! | F40: 3170 | G40: 857 | H40: 379 | I40: 19020 | J40: =(F40+G40+H40)/I40 -> 0.23165089 | K40: 18559 | L40: 240 | M40: #TeslaCoInnovation | N40: #FutureOfDriving | P40: =F40+G40+H40 -> 4406
...

Sheet Engagement Summary
A1: Week_Start_Date | B1: Platform | C1: New_Followers | D1: Unfollows | E1: Total_Followers | F1: Engagement_Rate | G1: Ad_Spend | H1: Growth Rate | I1: Engagement Volume | J1: Campaign Name
A2: 45656 | B2: Facebook | C2: 1980 | D2: 204 | E2: 379431 | F2: 3.09 | G2: 25140 | H2: =(C2-D2)/E2 -> 0.0046806929 | I2: =E2*(F2/100) -> 11724.418 | J2: =_xlfn.XLOOKUP(A2, 'Campaign Metadata'!$B$2:$B$5, 'Campaign Metadata'!$A$2:$A$5, "No Campaign", -1) -> FSDUpdate
A3: 45488 | B3: Instagram | C3: 1960 | D3: 115 | E3: 154169 | F3: 3.74 | G3: 10740 | H3: =(C3-D3)/E3 -> 0.011967386 | I3: =E3*(F3/100) -> 5765.9206 | J3: =_xlfn.XLOOKUP(A3, 'Campaign Metadata'!$B$2:$B$5, 'Campaign Metadata'!$A$2:$A$5, "No Campaign", -1) -> CybertruckLaunch
A4: 45698 | B4: Instagram | C4: 1957 | D4: 234 | E4: 222126 | F4: 4.61 | G4: 3314 | H4: =(C4-D4)/E4 -> 0.0077568587 | I4: =E4*(F4/100) -> 10240.009 | J4: =_xlfn.XLOOKUP(A4, 'Campaign Metadata'!$B$2:$B$5, 'Campaign Metadata'!$A$2:$A$5, "No Campaign", -1) -> FSDUpdate
A5: 45747 | B5: YouTube | C5: 1957 | D5: 490 | E5: 435726 | F5: 4.73 | G5: 15969 | H5: =(C5-D5)/E5 -> 0.0033667947 | I5: =E5*(F5/100) -> 20609.84 | J5: =_xlfn.XLOOKUP(A5, 'Campaign Metadata'!$B$2:$B$5, 'Campaign Metadata'!$A$2:$A$5, "No Campaign", -1) -> SustainabilityDrive
A6: 45782 | B6: Instagram | C6: 1957 | D6: 76 | E6: 447902 | F6: 6.09 | G6: 33381 | H6: =(C6-D6)/E6 -> 0.0041995794 | I6: =E6*(F6/100) -> 27277.232 | J6: =_xlfn.XLOOKUP(A6, 'Campaign Metadata'!$B$2:$B$5, 'Campaign Metadata'!$A$2:$A$5, "No Campaign", -1) -> SustainabilityDrive
A7: 45747 | B7: Twitter | C7: 1946 | D7: 270 | E7: 198350 | F7: 7.5 | G7: 11805 | H7: =(C7-D7)/E7 -> 0.0084497101 | I7: =E7*(F7/100) -> 14876.25 | J7: =_xlfn.XLOOKUP(A7, 'Campaign Metadata'!$B$2:$B$5, 'Campaign Metadata'!$A$2:$A$5, "No Campaign", -1) -> SustainabilityDrive
A8: 45572 | B8: Instagram | C8: 1939 | D8: 67 | E8: 187183 | F8: 6.25 | G8: 41215 | H8: =(C8-D8)/E8 -> 0.010000908 | I8: =E8*(F8/100) -> 11698.938 | J8: =_xlfn.XLOOKUP(A8, 'Campaign Metadata'!$B$2:$B$5, 'Campaign Metadata'!$A$2:$A$5, "No Campaign", -1) -> ModelYCampaign
A9: 45635 | B9: Twitter | C9: 1937 | D9: 210 | E9: 20607 | F9: 4.2 | G9: 20861 | H9: =(C9-D9)/E9 -> 0.083806474 | I9: =E9*(F9/100) -> 865.494 | J9: =_xlfn.XLOOKUP(A9, 'Campaign Metadata'!$B$2:$B$5, 'Campaign Metadata'!$A$2:$A$5, "No Campaign", -1) -> ModelYCampaign
A10: 45572 | B10: Facebook | C10: 1929 | D10: 267 | E10: 379363 | F10: 1.75 | G10: 43836 | H10: =(C10-D10)/E10 -> 0.0043810282 | I10: =E10*(F10/100) -> 6638.8525 | J10: =_xlfn.XLOOKUP(A10, 'Campaign Metadata'!$B$2:$B$5, 'Campaign Metadata'!$A$2:$A$5, "No Campaign", -1) -> ModelYCampaign
A11: 45565 | B11: YouTube | C11: 1918 | D11: 212 | E11: 94360 | F11: 7.36 | G11: 36851 | H11: =(C11-D11)/E11 -> 0.018079695 | I11: =E11*(F11/100) -> 6944.896 | J11: =_xlfn.XLOOKUP(A11, 'Campaign Metadata'!$B$2:$B$5, 'Campaign Metadata'!$A$2:$A$5, "No Campaign", -1) -> CybertruckLaunch
A12: 45558 | B12: Twitter | C12: 1911 | D12: 231 | E12: 268516 | F12: 8.55 | G12: 24018 | H12: =(C12-D12)/E12 -> 0.0062566104 | I12: =E12*(F12/100) -> 22958.118 | J12: =_xlfn.XLOOKUP(A12, 'Campaign Metadata'!$B$2:$B$5, 'Campaign Metadata'!$A$2:$A$5, "No Campaign", -1) -> CybertruckLaunch
A13: 45628 | B13: Facebook | C13: 1902 | D13: 196 | E13: 470269 | F13: 4.79 | G13: 26103 | H13: =(C13-D13)/E13 -> 0.0036277109 | I13: =E13*(F13/100) -> 22525.885 | J13: =_xlfn.XLOOKUP(A13, 'Campaign Metadata'!$B$2:$B$5, 'Campaign Metadata'!$A$2:$A$5, "No Campaign", -1) -> ModelYCampaign
... A201: 45684 | B201: Instagram | C201: 115 | D201: 281 | E201: 357265 | F201: 9.23 | G201: 25525 | H201: =(C201-D201)/E201 -> -0.00046464109 | I201: =E201*(F201/100) -> 32975.56 | J201: =_xlfn.XLOOKUP(A201, 'Campaign Metadata'!$B$2:$B$5, 'Campaign Metadata'!$A$2:$A$5, "No Campaign", -1) -> FSDUpdate

Sheet Campaign Metadata
A1: Campaign_Name | B1: Start_Date | C1: End_Date | D1: Objective | E1: Total_Budget | F1: Target_Platforms | G1: Primary_Hashtags | H1: Baseline Avg(Pre-Campaign) | I1: Campaign Avg(During) | J1: Uplift % | K1: Column1
A2: CybertruckLaunch | B2: 45458 | C2: 45488 | D2: Product Awareness | E2: 150000 | F2: Instagram,Facebook | G2: #EVRevolution,#TeslaCoInnovation | H2: =AVERAGEIFS('Engagement Summary'!F:F, 'Engagement Summary'!B:B, "*"&LEFT(F2,5)&"*", 'Engagement Summary'!A:A, "<"&B2, 'Engagement Summary'!A:A, ">="&B2-30) -> 8.555 | I2: =AVERAGEIFS('Engagement Summary'!F:F, 'Engagement Summary'!B:B, "*"&LEFT(F2,5)&"*", 'Engagement Summary'!A:A, ">="&B2, 'Engagement Summary'!A:A, "<="&C2) -> 6.244 | J2: =(I2-H2)/H2 -> -0.27013442
A3: ModelYCampaign | B3: 45566 | C3: 45596 | D3: Customer Engagement | E3: 200000 | F3: Instagram,YouTube | G3: #AnytimeIsTeslaTime, | H3: =AVERAGEIFS('Engagement Summary'!F:F, 'Engagement Summary'!B:B, "*"&LEFT(F3,5)&"*", 'Engagement Summary'!A:A, "<"&B3, 'Engagement Summary'!A:A, ">="&B3-30) -> 5.062 | I3: =AVERAGEIFS('Engagement Summary'!F:F, 'Engagement Summary'!B:B, "*"&LEFT(F3,5)&"*", 'Engagement Summary'!A:A, ">="&B3, 'Engagement Summary'!A:A, "<="&C3) -> 6.875 | J3: =(I3-H3)/H3 -> 0.35815883
A4: FSDUpdate | B4: 45651 | C4: 45667 | D4: Vehicle Launch | E4: 250000 | F4: Facebook,Twitter | G4: #SmoothLikeNitroTesla | H4: =AVERAGEIFS('Engagement Summary'!F:F, 'Engagement Summary'!B:B, "*"&LEFT(F4,5)&"*", 'Engagement Summary'!A:A, "<"&B4, 'Engagement Summary'!A:A, ">="&B4-30) -> 5.718 | I4: =AVERAGEIFS('Engagement Summary'!F:F, 'Engagement Summary'!B:B, "*"&LEFT(F4,5)&"*", 'Engagement Summary'!A:A, ">="&B4, 'Engagement Summary'!A:A, "<="&C4) -> 5.645 | J4: =(I4-H4)/H4 -> -0.012766702
A5: SustainabilityDrive | B5: 45717 | C5: 45747 | D5: Community Growth | E5: 180000 | F5: Instagram,Twitter | G5: #BetterWithTesla,#FutureOfDriving | H5: =AVERAGEIFS('Engagement Summary'!F:F, 'Engagement Summary'!B:B, "*"&LEFT(F5,5)&"*", 'Engagement Summary'!A:A, "<"&B5, 'Engagement Summary'!A:A, ">="&B5-30) -> 3.925 | I5: =AVERAGEIFS('Engagement Summary'!F:F, 'Engagement Summary'!B:B, "*"&LEFT(F5,5)&"*", 'Engagement Summary'!A:A, ">="&B5, 'Engagement Summary'!A:A, "<="&C5) -> 6.278 | J5: =(I5-H5)/H5 -> 0.59949045

Sheet Task 2.2
A1: ::Top 10 Tesla posts with highest engagement
A2: Post ID | B2: Platform | C2: Date | D2: Content Type | E2: Post Text | F2: Likes | G2: Shares | H2: Comments | I2: Impressions | J2: Engagement Rate | K2: Reach
A3: P220 | B3: Instagram | C3: 2024-06-02 | D3: Story | E3: Check out our latest story on instagram! | F3: 84 | G3: 897 | H3: 85 | I3: 588 | J3: =(F3+G3+H3)/I3 -> 1.8129252 | K3: 8
A4: P058 | B4: Instagram | C4: 2025-04-15 | D4: Reel | E4: Check out our latest reel on instagram! | F4: 103 | G4: 770 | H4: 19 | I4: 1030 | J4: =(F4+G4+H4)/I4 -> 0.86601942 | K4: 410
A5: P232 | B5: Twitter | C5: 2025-04-29 | D5: Story | E5: Check out our latest story on twitter! | F5: 249 | G5: 592 | H5: 230 | I5: 1494 | J5: =(F5+G5+H5)/I5 -> 0.71686747 | K5: 1044
A6: P178 | B6: Instagram | C6: 2024-11-07 | D6: Video | E6: Check out our latest video on instagram! | F6: 129 | G6: 643 | H6: 136 | I6: 1290 | J6: =(F6+G6+H6)/I6 -> 0.70387597 | K6: 839
A7: P175 | B7: Instagram | C7: 2025-01-17 | D7: Reel | E7: Check out our latest reel on instagram! | F7: 142 | G7: 784 | H7: 183 | I7: 1704 | J7: =(F7+G7+H7)/I7 -> 0.6508216 | K7: 995
A8: P062 | B8: Twitter | C8: 2024-11-22 | D8: Carousel | E8: Check out our latest carousel on twitter! | F8: 53 | G8: 81 | H8: 379 | I8: 954 | J8: =(F8+G8+H8)/I8 -> 0.53773585 | K8: 7
A9: P264 | B9: Twitter | C9: 2025-01-30 | D9: Image | E9: Check out our latest image on twitter! | F9: 59 | G9: 163 | H9: 93 | I9: 590 | J9: =(F9+G9+H9)/I9 -> 0.53389831 | K9: 475
A10: P143 | B10: YouTube | C10: 2024-10-02 | D10: Carousel | E10: Check out our latest carousel on youtube! | F10: 80 | G10: 362 | H10: 80 | I10: 1040 | J10: =(F10+G10+H10)/I10 -> 0.50192308 | K10: 349
A11: P210 | B11: YouTube | C11: 2025-02-19 | D11: Image | E11: Check out our latest image on youtube! | F11: 257 | G11: 966 | H11: 398 | I11: 3341 | J11: =(F11+G11+H11)/I11 -> 0.48518408 | K11: 2753
A12: P070 | B12: Facebook | C12: 2025-04-02 | D12: Video | E12: Check out our latest video on facebook! | F12: 199 | G12: 772 | H12: 400 | I12: 3582 | J12: =(F12+G12+H12)/I12 -> 0.38274707 | K12: 2988

Sheet Task 2.3.1
A2: ::Total Likes, Shares, Comments by Content Type & Platform
A3: Row Labels | B3: Sum of Likes | C3: Sum of Shares | D3: Sum of Comments
A4: Carousel | B4: 161999 | C4: 26471 | D4: 14508
A5: Facebook | B5: 44476 | C5: 7400 | D5: 4589
A6: Instagram | B6: 43948 | C6: 6975 | D6: 3890
A7: Twitter | B7: 48649 | C7: 5791 | D7: 3607
A8: YouTube | B8: 24926 | C8: 6305 | D8: 2422
A9: Image | B9: 173468 | C9: 29610 | D9: 16352
A10: Facebook | B10: 71602 | C10: 12904 | D10: 6495
A11: Instagram | B11: 34202 | C11: 5286 | D11: 2655
A12: Twitter | B12: 43761 | C12: 7110 | D12: 5125
A13: YouTube | B13: 23903 | C13: 4310 | D13: 2077
A14: Reel | B14: 127945 | C14: 23201 | D14: 11320
A15: Facebook | B15: 36368 | C15: 5964 | D15: 3353
... A33: YouTube | B33: 31285 | C33: 5586 | D33: 2589
A34: (blank)
A35: (blank)
A36: Grand Total | B36: 819991 | C36: 142925 | D36: 74851

Sheet Task 2.3.2
B3: ::Average Clicks per post by Hashtag
B4: Row Labels | C4: Average of Clicks
B5: #AnytimeIsTeslaTime | C5: 150.5
B6: #BetterWithTesla | C6: 170.5
B7: #EVRevolution | C7: 163.30682
B8: #FutureOfDriving | C8: 150.34737
B9: #SmoothLikeNitroTesla | C9: 101.75
B10: #TeslaCoInnovation | C10: 141.85263
B11: null
B12: (blank)
B13: Grand Total | C13: 151.22

Sheet Task 2.4
A2: ::Top-Performing Hashtags
A3: Row Labels | B3: Average of Engagement Rate
A4: #BetterWithTesla | B4: 0.20374469
A5: #AnytimeIsTeslaTime | B5: 0.18436005
A6: #TeslaCoInnovation | B6: 0.15525398
A7: #FutureOfDriving | B7: 0.15200123
A8: #EVRevolution | B8: 0.13091298
A9: #SmoothLikeNitroTesla | B9: 0.085110064
A10: (blank)
A11: null
A12: Grand Total | B12: 0.14828272

Sheet Task 3.1
A2: ::Platform with highest engagement
A3: Row Labels | B3: Average of Engagement
A4: Facebook | B4: 3677.6145
A5: YouTube | B5: 3609.1695
A6: Instagram | B6: 3336.443
A7: Twitter | B7: 3240.5696
A8: (blank)
A9: Grand Total | B9: 3459.2233

Sheet Task 3.2
A3: ::Follower growth rates across platforms
A4: Row Labels | B4: Average of Growth Rate
A5: Facebook | B5: 0.0054649907
A6: Instagram | B6: 0.0057625321
A7: Twitter | B7: 0.0092800257
A8: YouTube | B8: 0.0090210666
A9: (blank)
A10: Grand Total | B10: 0.0073821538

Sheet Task 3.3
A3: ::Engagement vs. Ad Spend per platform
A4: Row Labels | B4: Sum of Engagement_Rate | C4: Average of Ad_Spend
A5: Facebook | B5: 282.43 | C5: 27590.78
A6: Instagram | B6: 285.78 | C6: 23287.46
A7: Twitter | B7: 282.79 | C7: 21207.14
A8: YouTube | B8: 277.94 | C8: 24572.94
A9: (blank)
A10: Grand Total | B10: 1128.94 | C10: 24164.58

Sheet Task 3.4
C2: Should Tesla focus on Twitter + YouTube (product announcements + demos) or maintain a multi-platform strategy?
C4: Based on the previous analysis, the most effective approach for Tesla would be to maintain a multi-platform strategy, but with specific roles assigned to each channel based on their clear performance strengths.
C5: ​Each platform is currently winning in a different categories.
C6: :Facebook has the highest "Average of Engagement", making it the most reliable for overall interaction volume.
C7: :Twitter leads with a growth rate of 0.009280. It is best engine for expanding the brand's reach and building a new audience.
C8: :Instagram holds the highest "Sum of Engagement Rate" . While Facebook has volume, Instagram has the most "active" interest relative to the audience size.
C9: :Twitter is for Growth
C10: :​Facebook is for Efficiency
C11: :​Instagram is for Quality .
C12: :​YouTube is the "Middle Ground": YouTube shows consistent performance across growth and engagement.

Sheet Task 4.1
A2: ::Most frequently used Tesla hashtags.
A3: Row Labels | B3: Count of Individual Hashtags
A4: #TeslaCoInnovation | B4: 107
A5: #FutureOfDriving | B5: 103
A6: #EVRevolution | B6: 102
A7: #AnytimeIsTeslaTime | B7: 15
A8: #BetterWithTesla | B8: 7
A9: #SmoothLikeNitroTesla | B9: 5
A10: (blank)
A11: Grand Total | B11: 339

Sheet Task 4.2
A2: ::Average performance of posts containing each hashtag
A3: Row Labels | B3: Average of Engagement Rate
A4: P006 | B4: 0.1795416
A5: P008 | B5: 0.1034036
A6: P009 | B6: 0.088019732
A7: P011 | B7: 0.11571269
A8: P016 | B8: 0.075843714
A9: P022 | B9: 0.080294586
A10: P023 | B10: 0.076867995
A11: P030 | B11: 0.057655717
A12: P031 | B12: 0.28245271
A13: P037 | B13: 0.17770337
A14: P039 | B14: 0.072126494
A15: P042 | B15: 0.2184057
... A98: P298 | B98: 0.058563793
A99: (blank)
A100: Grand Total | B100: 0.15525398

Sheet Task 4.3
A2: ::Comparing content performance: Videos , Images and Carousels
A3: Row Labels | B3: Average of Engagement Rate | C3: Sum of Reach | D3: Sum of Clicks
A4: Carousel | B4: 0.17416554 | C4: 390987 | D4: 1790
A5: Image | B5: 0.15035568 | C5: 370491 | D5: 1581
A6: Video | B6: 0.12968338 | C6: 348581 | D6: 1046
A7: Grand Total | B7: 0.1521952 | C7: 1110059 | D7: 4417

Sheet Task 4.4
A2: ::Content type priorities per platform
A3: Platform | B3: Content Type | C3: Average of Engagement Rate | D3: Average of Impressions | E3: Average of Reach
A4: Facebook | B4: Story | C4: 0.15898978 | D4: 28969.273 | E4: 28358.909
B5: Video | C5: 0.12899654 | D5: 47053.333 | E5: 46548.333
B6: Image | C6: 0.11892683 | D6: 39665.96 | E6: 39002.68
B7: Carousel | C7: 0.1182059 | D7: 40390.786 | E7: 39865.571
B8: Reel | C8: 0.10810248 | D8: 44396.909 | E8: 43865.364
B9: Text | C9: 0.10743951 | D9: 34732.769 | E9: 34207.077
A10: Facebook Total | C10: 0.1219729 | D10: 39025.952 | E10: 38449.145
A11: Instagram | B11: Reel | C11: 0.26004033 | D11: 26077.769 | E11: 25570.615
B12: Story | C12: 0.24558274 | D12: 30044.941 | E12: 29561.706
B13: Video | C13: 0.20623961 | D13: 19733.25 | E13: 19194.583
B14: Image | C14: 0.14929862 | D14: 39353.9 | E14: 38819.3
B15: Carousel | C15: 0.1443986 | D15: 31475.529 | E15: 30981.824
B16: Text | C16: 0.12920449 | D16: 31055.9 | E16: 30429.3
A17: Instagram Total | C17: 0.19329258 | D17: 29439.949 | E17: 28917.456
A18: Twitter | B18: Story | C18: 0.18859717 | D18: 25415.111 | E18: 24831.333
B19: Carousel | C19: 0.15972488 | D19: 36355.294 | E19: 35824.882
B20: Image | C20: 0.14756648 | D20: 26339.895 | E20: 25808.053
B21: Reel | C21: 0.12428082 | D21: 37758.455 | E21: 37262.909
B22: Text | C22: 0.12088973 | D22: 37256.818 | E22: 36731.091
B23: Video | C23: 0.11980877 | D23: 32369.5 | E23: 31834.583
A24: Twitter Total | C24: 0.14368407 | D24: 32415.646 | E24: 31883.633
A25: YouTube | B25: Carousel | C25: 0.17416554 | D25: 36012.545 | E25: 35544.273
B26: Image | C26: 0.15035568 | D26: 41621.889 | E26: 41165.667
B27: Video | C27: 0.12968338 | D27: 35356.4 | E27: 34858.1
B28: Reel | C28: 0.11688584 | D28: 34422.167 | E28: 33813.75
B29: Text | C29: 0.11459218 | D29: 38568.5 | E29: 37974.25
B30: Story | C30: 0.09496533 | D30: 46943.778 | E30: 46382.222
A31: YouTube Total | C31: 0.13118494 | D31: 38447.576 | E31: 37916.237
A32: (blank) | B32: (blank)
A33: (blank) Total
A34: Grand Total | C34: 0.14828272 | D34: 34647.177 | E34: 34105.41

Sheet Task 5.1.1
A2: ::Total Impressions, Likes, Clicks per Campaign.
A3: Row Labels | B3: Sum of Impressions | C3: Sum of Likes | D3: Sum of Clicks
A4: CybertruckLaunch | B4: 1851380 | C4: 150208 | D4: 7261
A5: FSDUpdate | B5: 2353229 | C5: 184800 | D5: 10333
A6: ModelYCampaign | B6: 1895919 | C6: 137522 | D6: 8720
A7: SustainabilityDrive | B7: 2259795 | C7: 184657 | D7: 11569
A8: (blank) | B8: 2033830 | C8: 162804 | D8: 7483
A9: Grand Total | B9: 10394153 | C9: 819991 | D9: 45366
A10: :: Average Impressions, Likes, Clicks per Campaign.
A11: Row Labels | B11: Average of Impressions | C11: Average of Likes | D11: Average of Clicks
A12: CybertruckLaunch | B12: 38570.417 | C12: 3129.3333 | D12: 151.27083
A13: FSDUpdate | B13: 35122.821 | C13: 2758.209 | D13: 154.22388
A14: ModelYCampaign | B14: 32688.259 | C14: 2371.069 | D14: 150.34483
A15: SustainabilityDrive | B15: 31828.099 | C15: 2600.8028 | D15: 162.94366
A16: (blank) | B16: 36318.393 | C16: 2907.2143 | D16: 133.625
A17: Grand Total | B17: 34647.177 | C17: 2733.3033 | D17: 151.22

Sheet Task 5.1.2
A2: ::Engagement uplift during vs. before campaigns
A3: Row Labels | B3: Sum of Baseline Avg(Pre-Campaign) | C3: Sum of Campaign Avg(During)
A4: CybertruckLaunch | B4: 8.555 | C4: 6.244
A5: FSDUpdate | B5: 5.718 | C5: 5.645
A6: ModelYCampaign | B6: 5.062 | C6: 6.875
A7: SustainabilityDrive | B7: 3.925 | C7: 6.278
A8: (blank)
A9: Grand Total | B9: 23.26 | C9: 25.042

Sheet Task 5.2.1
A1: Week_Start_Date | B1: (All)
A2: ::Highest ROI
A3: Row Labels | B3: Sum of Ad_Spend | C3: Sum of Engagement Volume | D3: Sum of ROI
A4: Facebook | B4: 1379539 | C4: 780999.52 | D4: 0.5661308
A5: Instagram | B5: 1164373 | C5: 808238.42 | D5: 0.69414047
A6: Twitter | B6: 1060357 | C6: 776801.62 | D6: 0.73258498
A7: YouTube | B7: 1228647 | C7: 605086.52 | D7: 0.49248199
A8: (blank) | D8: #DIV/0!
A9: Grand Total | B9: 4832916 | C9: 2971126.1 | D9: 0.61476882

Sheet Task 5.2.2
A1: Platform | B1: (All)
A2: ::Campaign that drove the strongest follower growth
A3: Row Labels | B3: Sum of New_Followers
A4: CybertruckLaunch | B4: 60617
A5: ModelYCampaign | B5: 52416
A6: FSDUpdate | B6: 44920
A7: SustainabilityDrive | B7: 43623
A8: No Campaign | B8: 8552
A9: (blank)
A10: Grand Total | B10: 210128

Sheet Task 6.1
A2: ::Weekly follower growth per platform (line chart)
A3: Sum of New_Followers | B3: Column Labels
A4: Row Labels | B4: Facebook | C4: Instagram | D4: Twitter | E4: YouTube | F4: Grand Total
A5: 2024-07-08 | B5: 350 | C5: 1757 | D5: 987 | E5: 883 | F5: 3977
A6: Grand Total | B6: 350 | C6: 1757 | D6: 987 | E6: 883 | F6: 3977

Sheet Task 6.2
A2: ::Peak week of follower gain.
A3: Row Labels | B3: Sum of New_Followers
A4: 2024-12-30 | B4: 7075
A5: 2025-02-10 | B5: 6545
A6: 2025-03-31 | B6: 5924
A7: 2024-11-04 | B7: 5741
A8: 2024-12-16 | B8: 5721
A9: 2024-12-09 | B9: 5681
A10: 2024-09-09 | B10: 5594
A11: 2024-12-02 | B11: 5491
A12: 2024-12-23 | B12: 5284
A13: 2025-02-24 | B13: 5248
A14: 2025-04-21 | B14: 5190
A15: 2024-11-25 | B15: 5187
... A53: 2025-04-14 | B53: 1269
A54: (blank)
A55: Grand Total | B55: 210128

Sheet Task 6.3
A2: ::Using moving averages to smooth growth trends.
A3: Row Labels | B3: Sum of New_Followers
A4: <03-06-2024
A5: 2024 | B5: 128660
A6: 2025 | B6: 81468
A7: Grand Total | B7: 210128

Sheet Task 6.4

Sheet Conclusion
B2: Key Insights::
A3: 1 | B3: Instagram and Twitter provide higher engagement efficiency
A4: 2 | B4: Facebook generates the highest engagement but at higher cost
A5: 3 | B5: YouTube shows lower engagement despite significant ad spend
A6: 4 | B6: Campaigns significantly improve engagement rates
A7: 5 | B7: Sustainability-focused campaigns drive strong follower growth
A8: 6 | B8: Innovation-related hashtags perform best
B9: Recommendations::
A10: 1 | B10: Focus on Instagram and Twitter for cost-effective engagement
A11: 2 | B11: Optimize YouTube content strategy instead of increasing ad spend
A12: 3 | B12: Leverage campaign-based marketing for engagement spikes
A13: 4 | B13: Use high-performing hashtags consistently
A14: 5 | B14: Invest in sustainability and innovation messaging

Sheet Drive Link
F5: LINK:: | G5: https://drive.google.com/file/d/12SKJ4mV9gP7PGR89uggSEKEkzluKuAwQ/view?usp=sharing
